<?xml version="1.0" encoding="UTF-8"?>
<!-- Generated by org.testng.reporters.JUnitReportReporter -->
<testsuite hostname="SACHIN" name="ListenerInTestNG.TestCaseListener" tests="4" failures="1" timestamp="4 May 2021 06:33:09 GMT" time="0.030" errors="1">
  <testcase name="testcase2" time="0.005" classname="ListenerInTestNG.TestCaseListener"/>
  <testcase name="testcase3" time="0.010" classname="ListenerInTestNG.TestCaseListener">
    <failure type="java.lang.AssertionError" message="expected [true] but found [false]">
      <![CDATA[java.lang.AssertionError: expected [true] but found [false]
	at org.testng.Assert.fail(Assert.java:94)
	at org.testng.Assert.failNotEquals(Assert.java:513)
	at org.testng.Assert.assertEqualsImpl(Assert.java:135)
	at org.testng.Assert.assertEquals(Assert.java:116)
	at org.testng.Assert.assertEquals(Assert.java:305)
	at org.testng.Assert.assertEquals(Assert.java:315)
	at ListenerInTestNG.TestCaseListener.testcase3(TestCaseListener.java:27)
	at sun.reflect.NativeMethodAccessorImpl.invoke0(Native Method)
	at sun.reflect.NativeMethodAccessorImpl.invoke(Unknown Source)
	at sun.reflect.DelegatingMethodAccessorImpl.invoke(Unknown Source)
	at java.lang.reflect.Method.invoke(Unknown Source)
	at org.testng.internal.MethodInvocationHelper.invokeMethod(MethodInvocationHelper.java:100)
	at org.testng.internal.Invoker.invokeMethod(Invoker.java:646)
	at org.testng.internal.Invoker.invokeTestMethod(Invoker.java:811)
	at org.testng.internal.Invoker.invokeTestMethods(Invoker.java:1129)
	at org.testng.internal.TestMethodWorker.invokeTestMethods(TestMethodWorker.java:129)
	at org.testng.internal.TestMethodWorker.run(TestMethodWorker.java:112)
	at org.testng.TestRunner.privateRun(TestRunner.java:746)
	at org.testng.TestRunner.run(TestRunner.java:600)
	at org.testng.SuiteRunner.runTest(SuiteRunner.java:366)
	at org.testng.SuiteRunner.runSequentially(SuiteRunner.java:361)
	at org.testng.SuiteRunner.privateRun(SuiteRunner.java:319)
	at org.testng.SuiteRunner.run(SuiteRunner.java:268)
	at org.testng.SuiteRunnerWorker.runSuite(SuiteRunnerWorker.java:52)
	at org.testng.SuiteRunnerWorker.run(SuiteRunnerWorker.java:86)
	at org.testng.TestNG.runSuitesSequentially(TestNG.java:1264)
	at org.testng.TestNG.runSuitesLocally(TestNG.java:1189)
	at org.testng.TestNG.runSuites(TestNG.java:1104)
	at org.testng.TestNG.run(TestNG.java:1076)
	at org.testng.remote.AbstractRemoteTestNG.run(AbstractRemoteTestNG.java:126)
	at org.testng.remote.RemoteTestNG.initAndRun(RemoteTestNG.java:152)
	at org.testng.remote.RemoteTestNG.main(RemoteTestNG.java:57)
]]>
    </failure>
  </testcase> <!-- testcase3 -->
  <testcase name="testcase1" time="0.015" classname="ListenerInTestNG.TestCaseListener"/>
  <testcase name="testcase4" time="0.000" classname="ListenerInTestNG.TestCaseListener">
    <error type="java.lang.Throwable" message="Method TestCaseListener.testcase4()[pri:4, instance:ListenerInTestNG.TestCaseListener@29ee9faa] depends on not successfully finished methods">
      <![CDATA[java.lang.Throwable: Method TestCaseListener.testcase4()[pri:4, instance:ListenerInTestNG.TestCaseListener@29ee9faa] depends on not successfully finished methods
	at org.testng.internal.Invoker.invokeTestMethods(Invoker.java:1028)
	at org.testng.internal.TestMethodWorker.invokeTestMethods(TestMethodWorker.java:129)
	at org.testng.internal.TestMethodWorker.run(TestMethodWorker.java:112)
	at org.testng.TestRunner.privateRun(TestRunner.java:746)
	at org.testng.TestRunner.run(TestRunner.java:600)
	at org.testng.SuiteRunner.runTest(SuiteRunner.java:366)
	at org.testng.SuiteRunner.runSequentially(SuiteRunner.java:361)
	at org.testng.SuiteRunner.privateRun(SuiteRunner.java:319)
	at org.testng.SuiteRunner.run(SuiteRunner.java:268)
	at org.testng.SuiteRunnerWorker.runSuite(SuiteRunnerWorker.java:52)
	at org.testng.SuiteRunnerWorker.run(SuiteRunnerWorker.java:86)
	at org.testng.TestNG.runSuitesSequentially(TestNG.java:1264)
	at org.testng.TestNG.runSuitesLocally(TestNG.java:1189)
	at org.testng.TestNG.runSuites(TestNG.java:1104)
	at org.testng.TestNG.run(TestNG.java:1076)
	at org.testng.remote.AbstractRemoteTestNG.run(AbstractRemoteTestNG.java:126)
	at org.testng.remote.RemoteTestNG.initAndRun(RemoteTestNG.java:152)
	at org.testng.remote.RemoteTestNG.main(RemoteTestNG.java:57)
]]>
    </error>
  </testcase> <!-- testcase4 -->
</testsuite> <!-- ListenerInTestNG.TestCaseListener -->
